Workbook

Sheet Ozet
A1: GBSoft — Akıllı Otel Turu | Fiyatlandırma Modeli
A2: Solo geliştirme + AI agentic tooling, platforma devir + bakım modeli
A4: PARAMETRELER
A5: USD/TL kuru | B5: 40 | C5: ← Tahmin: Nisan 2026 ortalama. Değiştirebilirsin.
A6: Geliştirme süresi (ay) | B6: 6 | C6: ← Solo + AI agentic tooling ile gerçekçi süre
A7: Bakım süresi (ay) | B7: 24 | C7: ← Devir sonrası retainer süresi
A8: Hedef otel sayısı (üretim) | B8: 10 | C8: ← Platform üzerindeki tahmini otel sayısı (AI maliyet ölçeği için)
A10: AYLIK MASRAF ÖZETİ
A11: Kalem | B11: USD/ay | C11: TL/ay | D11: Notlar
A12: Geliştirme araçları (agentic + IDE + tasarım) | B12: =Geliştirme_Araclari!E20 | C12: =Geliştirme_Araclari!F20 | D12: Claude Max, Cursor, Copilot, Figma, vs.
A13: Sunucu, barındırma & altyapı (geliştirme/erken üretim) | B13: =Sunucu_Barindirma!E19 | C13: =Sunucu_Barindirma!F19 | D13: Vercel, Supabase, Cloudflare Stream, R2, vs.
A14: TOPLAM aylık (geliştirme dönemi) | B14: =SUM(B12:B13) | C14: =SUM(C12:C13)
A16: AI üretim maliyeti (otel başı, ÖNEMLİ: alıcı öder) | B16: =AI_Uretim!D27 | C16: =AI_Uretim!D28 | D16: ← Sözleşmede alıcının kendi LLM/STT/TTS hesabından ödenir
A18: GELİŞTİRME DÖNEMİ TOPLAM MASRAF (6 ay)
A19: Aylık masraf × ay | B19: =C14*B6 | C19: ← 6 ay tam zamanlı süre, hosting + tooling
A20: Yaşam gideri (kişisel, ortalama) | B20: 45000 | C20: ← Aylık kişisel yaşam gideri (Türkiye ortalama)
A21: Yaşam gideri × 6 ay | B21: =B20*B6
A22: TOPLAM 6 aylık runway | B22: =B19+B21
A24: MÜŞTERİ FİYAT TEKLİFİ — 3 SENARYO
A25: Senaryo | B25: Devir bedeli | C25: Bakım/ay | D25: Bakım toplamı | E25: Anlaşma toplamı | F25: Notlar
A26: A) Konservatif (alt sınır) | B26: 800000 | C26: 35000 | D26: =C26*$B$7 | E26: =B26+D26 | F26: İlk teklifin altına inilmez kırmızı çizgi
A27: B) Hedef (önerilen) | B27: 1000000 | C27: 50000 | D27: =C27*$B$7 | E27: =B27+D27 | F27: Kesinleşmiş hedef satış fiyatı
A28: C) Premium / anchor | B28: 1300000 | C28: 65000 | D28: =C28*$B$7 | E28: =B28+D28 | F28: İlk teklif (anchor); buradan inerek B'ye gel
A30: PROJE NET KÂR (Geliştirme + Bakım toplam süre)
A31: Toplam gelir (devir + bakım) | B31: =E27
A32: Geliştirme dönemi maliyet (6 ay) | B32: =-B22
A33: Bakım dönemi maliyet (Bakım süresi × tooling) | B33: =-Geliştirme_Araclari!E31*Ozet!B7 | C33: ← Bakım minimum stack: Claude Max + Cursor + GitHub + Notion + Muhasebe
A34: NET KÂR (24 ay) | B34: =SUM(B31:B33)
A35: Fiyat kaynakları (güncel resmi — kontrol tarihi Nisan 2026): • Postgres (self-hosted Docker) — VPS içinde, ayrı ücret yok; pg_dump→R2 backup. • DigitalOcean Droplet — digitalocean.com/pricing ($24/ay dev, $48/ay üretim); Docker Compose. • Bunny Stream — bunny.net/stream (encoding ücretsiz; $0.01/GB-ay depolama; $0.005/GB delivery Avrupa/TR). • Cloudflare R2 — developers.cloudflare.com/r2/pricing ($0.015/GB-ay). • Claude Max — claude.com/pricing/max (Max 5x $100/ay). • Cursor Pro — cursor.com/pricing ($20/ay). • Anthropic Claude API — docs.anthropic.com/pricing (örn. Sonnet $3/$15 per MTok). • OpenAI API — openai.com/api/pricing (Whisper $0.006/dk, ücretler modele göre). Özet USD satırları diğer sayfa referanslarından yeniden hesaplanır; TL = USD × Ozet!$B$5 kur tahmini.

Sheet Geliştirme_Araclari
A1: Geliştirme Araçları (Agentic + IDE + Tasarım + Operasyon)
A2: Solo geliştirici + AI agent tooling stack — aylık abonelik tabanlı
A4: Kategori | B4: Ürün | C4: Sağlayıcı | D4: Plan | E4: USD/ay | F4: TL/ay | G4: Notlar
A5: Agentic AI | B5: Claude Max 5x | C5: Anthropic | D5: Max 5x | E5: 100 | F5: =E5*Ozet!$B$5 | G5: claude.com/pricing/max — Max 5x $100/kişi/ay (web)
A6: Agentic AI | B6: Cursor Pro | C6: Cursor | D6: Pro | E6: 20 | F6: =E6*Ozet!$B$5 | G6: cursor.com/pricing — Pro $20/ay
A7: Agentic AI | B7: GitHub Copilot | C7: GitHub | D7: Kesildi | E7: 0 | F7: =E7*Ozet!$B$5 | G7: Cursor Pro ile çakışıyor — gereksiz
A8: API testing | B8: Anthropic API | C8: Anthropic | D8: PAYG | E8: 75 | F8: =E8*Ozet!$B$5 | G8: console.anthropic.com — API Sonnet $3/$15 per MTok (docs.anthropic.com)
A9: API testing | B9: OpenAI API | C9: OpenAI | D9: PAYG | E9: 25 | F9: =E9*Ozet!$B$5 | G9: platform.openai.com — GPT/API PAYG tahmini
A10: Geliştirme | B10: GitHub Pro | C10: GitHub | D10: Free | E10: 0 | F10: =E10*Ozet!$B$5 | G10: Free tier: sınırsız private repo, yeterli
A11: Geliştirme | B11: Vercel preview | C11: Vercel | D11: Pro | E11: 0 | F11: =E11*Ozet!$B$5 | G11: Hosting tarafında (Sunucu sayfasında)
A12: Tasarım | B12: Figma Pro | C12: Figma | D12: Free | E12: 0 | F12: =E12*Ozet!$B$5 | G12: Free tier: 3 proje — solo dev için yeterli
A13: Operasyon | B13: Notion | C13: Notion | D13: Free | E13: 0 | F13: =E13*Ozet!$B$5 | G13: Free tier: 1.000 blok — 6 ay için yeterli
A14: Operasyon | B14: Linear | C14: Linear | D14: Free | E14: 0 | F14: =E14*Ozet!$B$5 | G14: GitHub Issues ile ikame — ücretsiz
A15: Operasyon | B15: 1Password | C15: 1Password | D15: Free | E15: 0 | F15: =E15*Ozet!$B$5 | G15: Bitwarden free ile ikame
A16: Operasyon | B16: Loom | C16: Loom | D16: Free | E16: 0 | F16: =E16*Ozet!$B$5 | G16: Free tier: 25 video — handover için yeterli
... A18: Yasal/Muhasebe | B18: Sözleşme avukat | C18: Avukat | D18: Ertelendi | E18: 0 | F18: =E18*Ozet!$B$5 | G18: Sözleşme imzasında tek seferlik — aylık ayırma yok
A20: TOPLAM (USD/ay) | E20: =SUM(E5:E18) | F20: =SUM(F5:F18)
A22: YILLIK TOPLAM | E22: =E20*12 | F22: =F20*12
A24: Bakım dönemi minimum stack (devirden sonra)
A25: Ürün | B25: Sağlayıcı | C25: Plan | D25: USD/ay | E25: TL/ay | F25: Notlar
A26: Claude Max 5x | B26: Anthropic | C26: Max 5x | D26: 100 | E26: =D26*Ozet!$B$5 | F26: Bakım/küçük feature için yeterli
A27: Cursor Pro | B27: Cursor | C27: Pro | D27: 20 | E27: =D27*Ozet!$B$5 | F27: Düşürebilirsin ama önerilir
A28: GitHub Pro | B28: GitHub | C28: Pro | D28: 0 | E28: =D28*Ozet!$B$5 | F28: GitHub Free — yeterli
A29: Notion | B29: Notion | C29: Plus | D29: 0 | E29: =D29*Ozet!$B$5 | F29: Free tier ile devam
A30: Muhasebe | B30: Mali müşavir | C30: Aylık | D30: 0 | E30: =D30*Ozet!$B$5 | F30: Gerektiğinde devreye al
A31: BAKIM DÖNEMİ TOPLAM/ay | D31: =SUM(D26:D30) | E31: =SUM(E26:E30)

Sheet Sunucu_Barindirma
A1: Sunucu, Barındırma & Altyapı
A2: Geliştirme + erken üretim için. Devirden sonra alıcı kendi hesaplarına geçer.
A4: Kategori | B4: Servis | C4: Sağlayıcı | D4: Plan / Kullanım | E4: USD/ay | F4: TL/ay | G4: Notlar
A5: VPS + App + DB + Cache | B5: Docker (Next.js + Postgres + Redis + Nginx) | C5: DigitalOcean | D5: $24 Droplet (dev) / $48 üretim | E5: 24 | F5: =E5*Ozet!$B$5 | G5: digitalocean.com/pricing — Basic 2vCPU/4GB $24/ay; üretimde 4vCPU/8GB $48/ay; Docker Compose ile app+postgres+redis+nginx
A6: Database | B6: Postgres (self-hosted, Docker) | C6: DigitalOcean VPS | D6: VPS içinde (ayrı ücret yok) | E6: 0 | F6: =E6*Ozet!$B$5 | G6: VPS içindeki Docker container — postgres:16-alpine; veri /volumes/postgres; pg_dump→R2 backup günlük cron
A7: Cache/Queue | B7: Redis (self-hosted, Docker) | C7: DigitalOcean VPS | D7: VPS içinde (ayrı ücret yok) | E7: 0 | F7: =E7*Ozet!$B$5 | G7: VPS içindeki Docker container — redis:7-alpine; rate limiting, session cache, job state
A8: Object storage | B8: Görsel/dosya | C8: Cloudflare R2 | D8: PAYG | E8: 8 | F8: =E8*Ozet!$B$5 | G8: developers.cloudflare.com/r2/pricing — Standard $0.015/GB-ay (örnek ~530 GB≈$8)
A9: Video pipeline | B9: Encoding + delivery | C9: Bunny Stream | D9: PAYG | E9: 5 | F9: =E9*Ozet!$B$5 | G9: bunny.net/stream — encoding ÜCRETSİZ; depolama $0.01/GB-ay; delivery $0.005/GB (Avrupa/TR); signed token auth dahil
A10: CDN | B10: Statik içerik + WAF | C10: Cloudflare | D10: Free | E10: 0 | F10: =E10*Ozet!$B$5 | G10: Free tier dev için yeterli — üretimde Pro'ya geç
A11: Email | B11: Transactional email | C11: Resend | D11: Free | E11: 0 | F11: =E11*Ozet!$B$5 | G11: Free: 3.000 email/ay — dev için fazlası
A12: Monitoring | B12: Error tracking | C12: Sentry | D12: Free | E12: 0 | F12: =E12*Ozet!$B$5 | G12: Free tier hata takibi — dev için yeterli
A13: Analytics | B13: Product analytics | C13: PostHog | D13: Free → Growth | E13: 0 | F13: =E13*Ozet!$B$5 | G13: İlk başta free, ölçek geldikçe ücretli
A14: Domain | B14: Alan adı + DNS | C14: Cloudflare | D14: Yıllık (≈$12) | E14: 1 | F14: =E14*Ozet!$B$5 | G14: Ortalama aylık ($12/yıl)
A15: Yedekleme | B15: Otomatik backup | C15: Supabase + R2 | D15: Dahil | E15: 0 | F15: =E15*Ozet!$B$5 | G15: DB backup Pro plan dahil
A16: LLM Vector DB | B16: RAG için | C16: Pinecone | D16: pgvector (Supabase) | E16: 0 | F16: =E16*Ozet!$B$5 | G16: Supabase pgvector ile ikame — ayrı ödeme yok
A17: STT/TTS host | B17: Geliştirme/test | C17: OpenAI/ElevenLabs | D17: PAYG | E17: 25 | F17: =E17*Ozet!$B$5 | G17: openai.com/api/pricing — Whisper $0.006/dk; TTS karakter başına (API PAYG tahmini)
A19: TOPLAM (geliştirme + erken üretim) | E19: =SUM(E5:E17) | F19: =SUM(F5:F17)
A21: ÖNEMLİ: Devir sonrası alıcı kendi hesaplarına geçer; bu kalemler senin maliyetinden çıkar.

Sheet AI_Uretim
A1: AI Üretim Maliyetleri (Per-tour, Per-otel)
A2: Bu maliyetler ÜRETİMDE oluşur. Sözleşmede alıcı kendi hesabından öder — senin maliyetin değildir.
A4: PARAMETRELER
A5: Tur başına ortalama konuşma turn sayısı | B5: 12 | C5: İnsan + AI birer tur konuşma
A6: Turn başına ortalama input token (RAG dahil) | B6: 800 | C6: Otelin verisi context içinde
A7: Turn başına ortalama output token | B7: 200 | C7: AI cevabı
A8: Konuşma süresi (dakika) | B8: 5 | C8: STT ve TTS için
A9: Tur başına Whisper STT (USD/dakika) | B9: 0.006 | C9: openai.com/api/pricing — Whisper $0.006/dk
A10: Tur başına TTS (USD/dakika) | B10: 0.015 | C10: gpt-4o-mini-tts ≈ $0.015/dk (tahmini); alternatifler için aşağıdaki TTS tablosu
A11: Sonnet input ($/1M token) | B11: 3 | C11: Claude Sonnet 4.6
A12: Sonnet output ($/1M token) | B12: 15
A13: Haiku input ($/1M token) | B13: 1 | C13: Claude Haiku 4.5
A14: Haiku output ($/1M token) | B14: 5
A15: Otel başı aylık ortalama tur | B15: 300 | C15: Pilot dönem tahmini
A18: TUR BAŞI MALİYET HESABI
A19: Kalem | B19: Sonnet senaryosu (USD) | C19: Haiku senaryosu (USD) | D19: Hibrit (öneri) USD
A20: LLM input (turn × input × $/1M) | B20: =B5*B6/1000000*B11 | C20: =B5*B6/1000000*B13 | D20: =B5*B6/1000000*(B11*0.3+B13*0.7)
A21: LLM output (turn × output × $/1M) | B21: =B5*B7/1000000*B12 | C21: =B5*B7/1000000*B14 | D21: =B5*B7/1000000*(B12*0.3+B14*0.7)
A22: Whisper STT (dakika × $/dk) | B22: =B8*B9 | C22: =B8*B9 | D22: =B8*B9
A23: TTS (dakika × $/dk) | B23: =B8*B10 | C23: =B8*B10 | D23: =B8*B10
A24: TOPLAM tur başı | B24: =SUM(B20:B23) | C24: =SUM(C20:C23) | D24: =SUM(D20:D23)
A26: OTEL BAŞI AYLIK AI MALİYETİ
A27: USD/ay (otel başı) | B27: =B24*B15 | C27: =C24*B15 | D27: =D24*B15
A28: TL/ay (otel başı) | B28: =B27*Ozet!$B$5 | C28: =C27*Ozet!$B$5 | D28: =D27*Ozet!$B$5
A30: PLATFORM TOPLAMI (Özet'teki otel sayısı için)
A31: USD/ay platform toplam (hibrit) | B31: =D27*Ozet!B8 | C31: ← Otel sayısı: Ozet!B8'den
A32: TL/ay platform toplam (hibrit) | B32: =B31*Ozet!$B$5 | C32: ← Bu fatura sözleşmede ALICIYA aittir
A35: TTS MODEL KARŞILAŞTIRMASI (fiyat kontrolü: Ekim 2026)
A36: Dakika başına karakter (tahmin) | B36: 1000 | C36: Türkçe konuşma ≈ 900–1.000 karakter/dk
A37: Sesi açan misafir oranı | B37: 1 | C37: 1 = tavan senaryo; gerçekçi tahmin için 0,3 dene
A39: Model | B39: USD / 1M karakter | C39: USD / dakika | D39: Tur başı (USD) | E39: Otel başı / ay (USD) | F39: Platform / ay (USD) | G39: Not / kaynak
A40: OpenAI gpt-4o-mini-tts (sohbet — öneri) | C40: 0.015 | D40: =C40*$B$8*$B$37 | E40: =D40*$B$15 | F40: =E40*Ozet!$B$8 | G40: Token bazlı; ~$0.015/dk üçüncü taraf kaynak — resmi sayfadan teyit et
A41: Azure Neural TTS | B41: 15 | C41: =B41*$B$36/1000000 | D41: =C41*$B$8*$B$37 | E41: =D41*$B$15 | F41: =E41*Ozet!$B$8 | G41: tr-TR sesleri var; üçüncü taraf kaynak — teyit et
A42: Google Chirp 3 HD | B42: 30 | C42: =B42*$B$36/1000000 | D42: =C42*$B$8*$B$37 | E42: =D42*$B$15 | F42: =E42*Ozet!$B$8 | G42: cloud.google.com/text-to-speech/pricing — ilk 1M karakter/ay ücretsiz
A43: ElevenLabs Flash/Turbo | B43: 40 | C43: =B43*$B$36/1000000 | D43: =C43*$B$8*$B$37 | E43: =D43*$B$15 | F43: =E43*Ozet!$B$8 | G43: elevenlabs.io/pricing/api — $0.04/1K; abonelik paketi düşürür
A44: ElevenLabs v3 / Multilingual v2 (anlatım — öneri) | B44: 80 | C44: =B44*$B$36/1000000 | D44: =C44*$B$8*$B$37 | E44: =D44*$B$15 | F44: =E44*Ozet!$B$8 | G44: elevenlabs.io/pricing/api — $0.08/1K; sabit anlatım için
A46: ADIM ANLATIMI ÖN ÜRETİM (tek seferlik, otel başı)
A47: Otel başı anlatım karakteri (tüm adımlar × diller) | B47: 10000 | C47: Tahmin: ~10 adım × 500 karakter × 2 dil; bir kez üretilip R2'de saklanır
A48: Tek seferlik maliyet (ElevenLabs v3, USD) | B48: =B47/1000000*B44
A50: KENDİ GPU ALTERNATİFİ (API yerine)
...

Sheet 24_Ay_Senaryo
A1: 24 Ay Net Kâr / Zarar Senaryosu (Hedef anlaşma — B)
A2: Geliştirme dönemi (1-6 ay) → Devir (7. ay) → Bakım dönemi (7-30 ay)
A4: Ay | B4: Faz | C4: Devir geliri | D4: Bakım geliri | E4: Tooling masrafı | F4: Hosting masrafı | G4: Yaşam gideri | H4: Net (TL) | I4: Kümülatif (TL)
A5: 1 | B5: Geliştirme | C5: =Ozet!B27*0.3 | D5: 0 | E5: =-Geliştirme_Araclari!F20 | F5: =-Sunucu_Barindirma!F19 | G5: =-Ozet!B20 | H5: =SUM(C5:G5) | I5: =H5
A6: 2 | B6: Geliştirme | C6: 0 | D6: 0 | E6: =-Geliştirme_Araclari!F20 | F6: =-Sunucu_Barindirma!F19 | G6: =-Ozet!B20 | H6: =SUM(C6:G6) | I6: =I5+H6
A7: 3 | B7: Geliştirme | C7: 0 | D7: 0 | E7: =-Geliştirme_Araclari!F20 | F7: =-Sunucu_Barindirma!F19 | G7: =-Ozet!B20 | H7: =SUM(C7:G7) | I7: =I6+H7
A8: 4 | B8: Geliştirme | C8: 0 | D8: 0 | E8: =-Geliştirme_Araclari!F20 | F8: =-Sunucu_Barindirma!F19 | G8: =-Ozet!B20 | H8: =SUM(C8:G8) | I8: =I7+H8
A9: 5 | B9: Geliştirme | C9: 0 | D9: 0 | E9: =-Geliştirme_Araclari!F20 | F9: =-Sunucu_Barindirma!F19 | G9: =-Ozet!B20 | H9: =SUM(C9:G9) | I9: =I8+H9
A10: 6 | B10: Geliştirme | C10: 0 | D10: 0 | E10: =-Geliştirme_Araclari!F20 | F10: =-Sunucu_Barindirma!F19 | G10: =-Ozet!B20 | H10: =SUM(C10:G10) | I10: =I9+H10
A11: 7 | B11: Devir / Handover | C11: =Ozet!B27*0.5 | D11: =Ozet!C27 | E11: =-Geliştirme_Araclari!E31 | F11: =-Sunucu_Barindirma!F19 | G11: 0 | H11: =SUM(C11:G11) | I11: =I10+H11
A12: 8 | B12: Bakım | C12: =Ozet!B27*0.2 | D12: =Ozet!C27 | E12: =-Geliştirme_Araclari!E31 | F12: 0 | G12: 0 | H12: =SUM(C12:G12) | I12: =I11+H12
A13: 9 | B13: Bakım | C13: 0 | D13: =Ozet!C27 | E13: =-Geliştirme_Araclari!E31 | F13: 0 | G13: 0 | H13: =SUM(C13:G13) | I13: =I12+H13
A14: 10 | B14: Bakım | C14: 0 | D14: =Ozet!C27 | E14: =-Geliştirme_Araclari!E31 | F14: 0 | G14: 0 | H14: =SUM(C14:G14) | I14: =I13+H14
A15: 11 | B15: Bakım | C15: 0 | D15: =Ozet!C27 | E15: =-Geliştirme_Araclari!E31 | F15: 0 | G15: 0 | H15: =SUM(C15:G15) | I15: =I14+H15
A16: 12 | B16: Bakım | C16: 0 | D16: =Ozet!C27 | E16: =-Geliştirme_Araclari!E31 | F16: 0 | G16: 0 | H16: =SUM(C16:G16) | I16: =I15+H16
A17: 13 | B17: Bakım | C17: 0 | D17: =Ozet!C27 | E17: =-Geliştirme_Araclari!E31 | F17: 0 | G17: 0 | H17: =SUM(C17:G17) | I17: =I16+H17
A18: 14 | B18: Bakım | C18: 0 | D18: =Ozet!C27 | E18: =-Geliştirme_Araclari!E31 | F18: 0 | G18: 0 | H18: =SUM(C18:G18) | I18: =I17+H18
A19: 15 | B19: Bakım | C19: 0 | D19: =Ozet!C27 | E19: =-Geliştirme_Araclari!E31 | F19: 0 | G19: 0 | H19: =SUM(C19:G19) | I19: =I18+H19
A20: 16 | B20: Bakım | C20: 0 | D20: =Ozet!C27 | E20: =-Geliştirme_Araclari!E31 | F20: 0 | G20: 0 | H20: =SUM(C20:G20) | I20: =I19+H20
A21: 17 | B21: Bakım | C21: 0 | D21: =Ozet!C27 | E21: =-Geliştirme_Araclari!E31 | F21: 0 | G21: 0 | H21: =SUM(C21:G21) | I21: =I20+H21
A22: 18 | B22: Bakım | C22: 0 | D22: =Ozet!C27 | E22: =-Geliştirme_Araclari!E31 | F22: 0 | G22: 0 | H22: =SUM(C22:G22) | I22: =I21+H22
A23: 19 | B23: Bakım | C23: 0 | D23: =Ozet!C27*1.2 | E23: =-Geliştirme_Araclari!E31 | F23: 0 | G23: 0 | H23: =SUM(C23:G23) | I23: =I22+H23
A24: 20 | B24: Bakım | C24: 0 | D24: =Ozet!C27*1.2 | E24: =-Geliştirme_Araclari!E31 | F24: 0 | G24: 0 | H24: =SUM(C24:G24) | I24: =I23+H24
A25: 21 | B25: Bakım | C25: 0 | D25: =Ozet!C27*1.2 | E25: =-Geliştirme_Araclari!E31 | F25: 0 | G25: 0 | H25: =SUM(C25:G25) | I25: =I24+H25
A26: 22 | B26: Bakım | C26: 0 | D26: =Ozet!C27*1.2 | E26: =-Geliştirme_Araclari!E31 | F26: 0 | G26: 0 | H26: =SUM(C26:G26) | I26: =I25+H26
A27: 23 | B27: Bakım | C27: 0 | D27: =Ozet!C27*1.2 | E27: =-Geliştirme_Araclari!E31 | F27: 0 | G27: 0 | H27: =SUM(C27:G27) | I27: =I26+H27
A28: 24 | B28: Bakım | C28: 0 | D28: =Ozet!C27*1.2 | E28: =-Geliştirme_Araclari!E31 | F28: 0 | G28: 0 | H28: =SUM(C28:G28) | I28: =I27+H28
A29: 25 | B29: Bakım | C29: 0 | D29: =Ozet!C27*1.2 | E29: =-Geliştirme_Araclari!E31 | F29: 0 | G29: 0 | H29: =SUM(C29:G29) | I29: =I28+H29
A30: 26 | B30: Bakım | C30: 0 | D30: =Ozet!C27*1.2 | E30: =-Geliştirme_Araclari!E31 | F30: 0 | G30: 0 | H30: =SUM(C30:G30) | I30: =I29+H30
A31: 27 | B31: Bakım | C31: 0 | D31: =Ozet!C27*1.2 | E31: =-Geliştirme_Araclari!E31 | F31: 0 | G31: 0 | H31: =SUM(C31:G31) | I31: =I30+H31
A32: 28 | B32: Bakım | C32: 0 | D32: =Ozet!C27*1.2 | E32: =-Geliştirme_Araclari!E31 | F32: 0 | G32: 0 | H32: =SUM(C32:G32) | I32: =I31+H32
A33: 29 | B33: Bakım | C33: 0 | D33: =Ozet!C27*1.2 | E33: =-Geliştirme_Araclari!E31 | F33: 0 | G33: 0 | H33: =SUM(C33:G33) | I33: =I32+H33
A34: 30 | B34: Bakım | C34: 0 | D34: =Ozet!C27*1.2 | E34: =-Geliştirme_Araclari!E31 | F34: 0 | G34: 0 | H34: =SUM(C34:G34) | I34: =I33+H34
A36: TOPLAM 30 AY | C36: =SUM(C5:C34) | D36: =SUM(D5:D34) | E36: =SUM(E5:E34) | F36: =SUM(F5:F34) | G36: =SUM(G5:G34) | H36: =SUM(H5:H34) | I36: =I34

Sheet Sozlesme_Maddeleri
A1: Müşteri Sözleşme Maddeleri & Fiyat Yapısı
A2: Bu sayfa anlaşma yapısı + paramların hatırlatıcı listesi. Excel formülünden bağımsız notlardır.
A4: DEVİR BEDELİ ÖDEME PLANI
A5: Madde | B5: Değer | C5: Açıklama
A6: İmza üzerine peşin | B6: %30 | C6: Sözleşme imzasında ödenir
A7: Handover (kod + dökümantasyon teslim) | B7: %50 | C7: Repo/sırlar geçişi sonrası 7 gün içinde
A8: Stabilite kanıtı | B8: %20 | C8: Üretimde 30 gün hatasız çalıştıktan sonra
A10: BAKIM ANLAŞMASI KAPSAMI
A11: Madde | B11: Değer | C11: Açıklama
A12: Aylık taahhüt saati | B12: 30-50 saat | C12: Üzeri saatlik 2.000 TL/saat (yeni feature)
A13: Kritik bug response | B13: 24 saat | C13: Üretimi durduran hatalar
A14: Standart bug fix | B14: 5 iş günü | C14: Hafif/orta seviye
A15: Yeni feature | B15: Ayrı ücret | C15: Saatlik 2.000 TL veya proje bazlı teklif
A16: Çalışma saatleri | B16: Mesai içi (TR saati) | C16: Acil durumda esneklik müzakere
A17: Bakım enflasyon ayarı | B17: Yıllık %20 veya TÜFE | C17: Sözleşmede mutlaka olsun
A19: SÖZLEŞMEDE OLMAZSA OLMAZLAR
A20: Madde | B20: Değer | C20: Açıklama
A21: AI API maliyetleri | B21: Alıcı öder | C21: OpenAI/Anthropic faturası alıcının hesabından
A22: Hosting maliyetleri | B22: Alıcı öder (devirden sonra) | C22: Vercel, Supabase, CDN — alıcıya geçer
A23: Non-compete sınırı | B23: 12-18 ay, TR otel sektörü | C23: Dünya geneli sonsuz kabul ETME
A24: Source code escrow | B24: İmzaya kadar repo paylaşma | C24: Demo + ekran kaydı yeterli
A25: Stabilite garantisi | B25: 30 gün post-handover | C25: Bu süre boyunca kritik bug ücretsiz
A26: IP devri kapsamı | B26: Kod + tasarım + marka + dökümantasyon | C26: Açıkça listele
A27: Sona erdirme şartları | B27: 60 gün önceden bildirim | C27: Ani fesih senaryosunu engelle
A29: FİYATLANDIRMA NOTLARI
A30: Madde | B30: Değer | C30: Açıklama
A31: İlk teklif anchor | B31: Premium senaryo (C) | C31: 1.3M peşin + 65k/ay olarak başla
A32: Pazarlık hedefi | B32: Hedef senaryo (B) | C32: 1M peşin + 50k/ay'a inilebilir
A33: Mutlak alt sınır | B33: Konservatif senaryo (A) | C33: 800k peşin + 35k/ay altı kabul ETME
A34: Yıllık peşin indirim | B34: %15 indirim | C34: Bakımı yıllık peşin ödeyene
A35: Eklenen otel/property primi | B35: %30-40 sürşarj | C35: Multi-property ölçeklenirse

Sheet Canli_AltYapi
A1: Canlı altyapı (üretim) — Geliştirme araçları (IDE, agent abonelikleri) hariç
A2: Barındırma (Vercel), veritabanı (Supabase/Postgres), video (Cloudflare Stream), depolama (R2), e-posta, hata/ürün analitiği, cache (Redis), alan adı, opsiyonel CF Pro. Yapay zekâ API (LLM/STT/TTS) ayrı kalem: kullanım başı — ayrıntı AI_Uretim sayfası.
A4: PARAMETRELER
A5: USD/TL kuru (Ozet B5 referansı) | B5: =Ozet!$B$5 | D5: Kur; TL sütunları = USD × bu hücre. Nisan 2026 tahmini Ozet’te 40 olabilir.
A6: Katalog toplam video (dk) — Stream saklama hacmi | B6: 2500 | D6: Tüm turların depodaki toplam dakikası. Cloudflare: 5 USD / 1000 dk saklama
A7: Aylık toplam izlenen video (dk) — Stream delivery | B7: 50000 | D7: Aylık oynatılan toplam dakika. Cloudflare: 1 USD / 1000 dk — ana değişken gider
A9: Kalem | B9: USD/ay | C9: TL/ay | D9: Notlar (kaynak: sağlayıcı fiyat sayfaları, 2025–2026)
A10: Vercel Pro — platform + 1 koltuk (taban) | B10: 20 | C10: =B10*$B$5 | D10: vercel.com/pricing — ayrıca kullanım kredisi/edge; trafik arttıkça artar
A11: Vercel — edge/bandwidth/görüntü (tahmini ek) | B11: 30 | C11: =B11*$B$5 | D11: Düşük-orta trafik için tahmini; yüksek trafikte 50–200+ olabilir
A12: Supabase Pro — taban (Postgres, Auth, Storage kotaları) | B12: 25 | C12: =B12*$B$5 | D12: supabase.com/pricing
A13: Supabase — compute + MAU/egress aşımı (tahmini) | B13: 40 | C13: =B13*$B$5 | D13: Büyüyünce; tek başına 25–150 USD bandı tipik (MAU, egress, large compute)
A14: Cloudflare R2 — nesne depolama (görsel, export, yedek) | B14: 8 | C14: =B14*$B$5 | D14: 0,015 USD/GB-ay; egress yok — developers.cloudflare.com/r2/pricing
A15: Cloudflare Stream — video saklama (formül) | B15: =ROUND($B$6/1000*5,2) | C15: =B15*$B$5 | D15: 5 USD / 1000 dakika; B6 = katalog toplam dk
A16: Cloudflare Stream — video oynatma / delivery (formül) | B16: =ROUND($B$7/1000*1,2) | C16: =B16*$B$5 | D16: 1 USD / 1000 izlenen dakika; B7 = aylık delivery dk
A17: Cloudflare (Pro) — WAF/özel ihtiyaç (opsiyonel) | B17: 0 | C17: =B17*$B$5 | D17: Gerekirse; Stream’den ayrı — cloudflare.com/plans
A18: Resend — transactional e-posta | B18: 0 | C18: =B18*$B$5 | D18: Kota içi ücretsiz; 50k+ e-posta için Pro ~20 USD — resend.com/pricing
A19: Sentry — hata izleme (Team, tipik) | B19: 26 | C19: =B19*$B$5 | D19: Yıllık faturalamada ~26; aylık farklı — sentry.io/pricing; ücretsiz Developer alternatif
A20: PostHog — ürün analitiği | B20: 0 | C20: =B20*$B$5 | D20: 1M event/ay ücretsiz; üstü pay-as-you-go — posthog.com/pricing
A21: Upstash — Redis (cache, rate limit, kuyruk) | B21: 10 | C21: =B21*$B$5 | D21: Sabit 10+ veya PAYG; upstash.com/pricing
A22: Edge Functions / arka plan (Supabase, CF Workers) aşım (tahmini) | B22: 15 | C22: =B22*$B$5 | D22: İş yüküne göre; düşük başlangıçta 0–15 USD
A23: Alan adı + DNS (ortalama/ay) | B23: 1.5 | C23: =B23*$B$5 | D23: Yıllık ~18 USD / 12
A24: Yedekleme / PITR eklentisi (Supabase, opsiyonel) | B24: 0 | C24: =B24*$B$5 | D24: Gerekirse ayrı satır; Supabase fiyat listesi
A25: Beklenmeyen transfer / e-posta aşımı (tampon) | B25: 10 | C25: =B25*$B$5 | D25: Egress veya sürpriz kalemler için küçük tampon
A26: TOPLAM (altyapı + video formülleri) | B26: =SUM(B10:B25) | C26: =SUM(C10:C25) | D26: B6/B7 değiştikçe Stream satırları ve toplam güncellenir
A28: Yapay zekâ API (OpenAI, Anthropic, STT, TTS, embedding): Bu sayfaya dahil DEĞİL. Aylık toplam = kullanım × birim fiyat; tahmin için AI_Uretim sayfasındaki parametreler.
